<robot
  name="cube_pillars">
  <link
    name="base_global_link">
    <inertial>
      <origin
        xyz="3.7297E-17 1.5836E-15 0.15167"
        rpy="0 0 0" />
      <mass
        value="0.59402" />
      <inertia
        ixx="0.0037192"
        ixy="-1.6783E-20"
        ixz="-6.3649E-19"
        iyy="0.0080768"
        iyz="-3.8004E-17"
        izz="0.0044468" />
    </inertial>
    <visual>
      <origin
        xyz="0 0 0"
        rpy="0 0 0" />
      <geometry>
        <mesh
          filename="package://cube_pillars/meshes/base_global_link.STL" />
      </geometry>
      <material
        name="">
        <color
          rgba="0.79216 0.81961 0.93333 1" />
      </material>
    </visual>
    <collision>
      <origin
        xyz="0 0 0"
        rpy="0 0 0" />
      <geometry>
        <mesh
          filename="package://cube_pillars/meshes/base_global_link.STL" />
      </geometry>
    </collision>
  </link>
  <link
    name="hook_link">
    <inertial>
      <origin
        xyz="0.0018383 -0.0040417 -0.07992"
        rpy="0 0 0" />
      <mass
        value="0.1989" />
      <inertia
        ixx="0.00050844"
        ixy="3.079E-06"
        ixz="-6.1575E-06"
        iyy="0.00050602"
        iyz="-1.0434E-05"
        izz="0.00052641" />
    </inertial>
    <visual>
      <origin
        xyz="0 0 0"
        rpy="0 0 0" />
      <geometry>
        <mesh
          filename="package://cube_pillars/meshes/hook_link.STL" />
      </geometry>
      <material
        name="">
        <color
          rgba="1 1 1 1" />
      </material>
    </visual>
    <collision>
      <origin
        xyz="0 0 0"
        rpy="0 0 0" />
      <geometry>
        <mesh
          filename="package://cube_pillars/meshes/hook_link.STL" />
      </geometry>
    </collision>
  </link>
  <joint
    name="hook_joint"
    type="continuous">
    <origin
      xyz="0 0 0.19"
      rpy="0 0 0" />
    <parent
      link="base_global_link" />
    <child
      link="hook_link" />
    <axis
      xyz="0 0 1" />
  </joint>
  <link
    name="components_link">
    <inertial>
      <origin
        xyz="-0.019545 -0.0046739 0.032907"
        rpy="0 0 0" />
      <mass
        value="0.06292" />
      <inertia
        ixx="4.4926E-05"
        ixy="6.032E-06"
        ixz="6.4596E-06"
        iyy="3.9747E-05"
        iyz="-5.3189E-06"
        izz="6.2709E-05" />
    </inertial>
    <visual>
      <origin
        xyz="0 0 0"
        rpy="0 0 0" />
      <geometry>
        <mesh
          filename="package://cube_pillars/meshes/components_link.STL" />
      </geometry>
      <material
        name="">
        <color
          rgba="0.79216 0.81961 0.93333 1" />
      </material>
    </visual>
    <collision>
      <origin
        xyz="0 0 0"
        rpy="0 0 0" />
      <geometry>
        <mesh
          filename="package://cube_pillars/meshes/components_link.STL" />
      </geometry>
    </collision>
  </link>
  <joint
    name="components_joint"
    type="fixed">
    <origin
      xyz="0.0048505 -0.056659 -0.086037"
      rpy="1.5708 0 3.1416" />
    <parent
      link="hook_link" />
    <child
      link="components_link" />
    <axis
      xyz="0 0 0" />
  </joint>
  <link
    name="x_wheel_link">
    <inertial>
      <origin
        xyz="0 0 0.00075"
        rpy="0 0 0" />
      <mass
        value="0.020913" />
      <inertia
        ixx="1.0298E-05"
        ixy="-2.1176E-22"
        ixz="-3.6746E-24"
        iyy="1.0298E-05"
        iyz="-2.5406E-25"
        izz="2.0587E-05" />
    </inertial>
    <visual>
      <origin
        xyz="0 0 0"
        rpy="0 0 0" />
      <geometry>
        <mesh
          filename="package://cube_pillars/meshes/x_wheel_link.STL" />
      </geometry>
      <material
        name="">
        <color
          rgba="0.89804 0.91765 0.92941 1" />
      </material>
    </visual>
    <collision>
      <origin
        xyz="0 0 0"
        rpy="0 0 0" />
      <geometry>
        <mesh
          filename="package://cube_pillars/meshes/x_wheel_link.STL" />
      </geometry>
    </collision>
  </link>
  <joint
    name="x_wheel_joint"
    type="continuous">
    <origin
      xyz="-0.03936 -0.0046597 -0.086939"
      rpy="-1.5708 -0.31401 1.5708" />
    <parent
      link="hook_link" />
    <child
      link="x_wheel_link" />
    <axis
      xyz="0 0 -1" />
    <limit
      effort="1"
      velocity="1000" />
  </joint>
  <link
    name="y_wheel_link">
    <inertial>
      <origin
        xyz="2.1684E-19 0 0.00075"
        rpy="0 0 0" />
      <mass
        value="0.020913" />
      <inertia
        ixx="1.0298E-05"
        ixy="2.9646E-21"
        ixz="8.2298E-24"
        iyy="1.0298E-05"
        iyz="-4.0619E-24"
        izz="2.0587E-05" />
    </inertial>
    <visual>
      <origin
        xyz="0 0 0"
        rpy="0 0 0" />
      <geometry>
        <mesh
          filename="package://cube_pillars/meshes/y_wheel_link.STL" />
      </geometry>
      <material
        name="">
        <color
          rgba="0.89804 0.91765 0.92941 1" />
      </material>
    </visual>
    <collision>
      <origin
        xyz="0 0 0"
        rpy="0 0 0" />
      <geometry>
        <mesh
          filename="package://cube_pillars/meshes/y_wheel_link.STL" />
      </geometry>
    </collision>
  </link>
  <joint
    name="y_wheel_joint"
    type="continuous">
    <origin
      xyz="0.0047528 -0.0046591 -0.042827"
      rpy="2.9871E-16 -1.172E-16 1.0096" />
    <parent
      link="hook_link" />
    <child
      link="y_wheel_link" />
    <axis
      xyz="0 0 1" />
    <limit
      effort="1"
      velocity="1000" />
  </joint>
  <link
    name="z_wheel_link">
    <inertial>
      <origin
        xyz="0 -1.3878E-17 -0.00075"
        rpy="0 0 0" />
      <mass
        value="0.020913" />
      <inertia
        ixx="1.0298E-05"
        ixy="4.2352E-22"
        ixz="8.2746E-24"
        iyy="1.0298E-05"
        iyz="1.2707E-23"
        izz="2.0587E-05" />
    </inertial>
    <visual>
      <origin
        xyz="0 0 0"
        rpy="0 0 0" />
      <geometry>
        <mesh
          filename="package://cube_pillars/meshes/z_wheel_link.STL" />
      </geometry>
      <material
        name="">
        <color
          rgba="0.89804 0.91765 0.92941 1" />
      </material>
    </visual>
    <collision>
      <origin
        xyz="0 0 0"
        rpy="0 0 0" />
      <geometry>
        <mesh
          filename="package://cube_pillars/meshes/z_wheel_link.STL" />
      </geometry>
    </collision>
  </link>
  <joint
    name="z_wheel_joint"
    type="continuous">
    <origin
      xyz="0.0047528 0.042953 -0.08794"
      rpy="-1.5708 -0.47731 -1.9742E-08" />
    <parent
      link="hook_link" />
    <child
      link="z_wheel_link" />
    <axis
      xyz="0 0 1" />
    <limit
      effort="1"
      velocity="1000" />
  </joint>
</robot>