<robot
  name="cube_pillars">
  <link
    name="base_global_link">
    <inertial>
      <origin
        xyz="3.7297E-17 1.5836E-15 0.15167"
        rpy="0 0 0" />
      <mass
        value="200.59402" />
      <inertia
        ixx="20.5"
        ixy="0"
        ixz="0"
        iyy="20.5"
        iyz="0"
        izz="20.5" />
    </inertial>
    <visual>
      <origin
        xyz="0 0 0"
        rpy="0 0 0" />
      <geometry>
        <mesh
          filename="package://cube_pillars/meshes/base_global_link.STL" />
      </geometry>
      <material
        name="">
        <color rgba="0.0 0.0 0.9 0.7" />
      </material>
    </visual>
    <collision>
      <origin
        xyz="0 0 0"
        rpy="0 0 0" />
      <geometry>
        <mesh
          filename="package://cube_pillars/meshes/base_global_link.STL" />
      </geometry>
    </collision>
  </link>
  <link
    name="hook_link">
    <inertial>
      <origin
        xyz="0.0018383 -0.0040417 -0.07992"
        rpy="0 0 0" />
      <mass
        value="0.1989" />
      <inertia
        ixx="0.00050844"
        ixy="3.079E-06"
        ixz="-6.1575E-06"
        iyy="0.00050602"
        iyz="-1.0434E-05"
        izz="0.00052641" />
    </inertial>
    <visual>
      <origin
        xyz="0 0 0"
        rpy="0 0 0" />
      <geometry>
        <mesh
          filename="package://cube_pillars/meshes/hook_link.STL" />
      </geometry>
      <material name="">
        <color rgba="0.66 0.66 0.66 0.6" />
      </material>
    </visual>
    <collision>
      <origin
        xyz="0 0 0"
        rpy="0 0 0" />
      <geometry>
        <mesh
          filename="package://cube_pillars/meshes/hook_link.STL" />
      </geometry>
    </collision>
  </link>
  <joint
    name="hook_joint"
    type="continuous">
    <origin
      xyz="0 0 0.19"
      rpy="0 0 0" />
    <parent
      link="base_global_link" />
    <child
      link="hook_link" />
    <axis
      xyz="0 0 1" />
  </joint>
  <link
    name="components_link">
    <inertial>
      <origin
        xyz="-0.019545 -0.0046739 0.032907"
        rpy="0 0 0" />
      <mass
        value="0.06292" />
      <inertia
        ixx="4.4926E-05"
        ixy="6.032E-06"
        ixz="6.4596E-06"
        iyy="3.9747E-05"
        iyz="-5.3189E-06"
        izz="6.2709E-05" />
    </inertial>
    <visual>
      <origin
        xyz="0 0 0"
        rpy="0 0 0" />
      <geometry>
        <mesh
          filename="package://cube_pillars/meshes/components_link.STL" />
      </geometry>
      <material name="">
        <color rgba="0.0 0.9 0.0 0.7" />
      </material>
    </visual>
    <collision>
      <origin
        xyz="0 0 0"
        rpy="0 0 0" />
      <geometry>
        <mesh
          filename="package://cube_pillars/meshes/components_link.STL" />
      </geometry>
    </collision>
  </link>
  <joint
    name="components_joint"
    type="fixed">
    <origin
      xyz="0.0048505 -0.056659 -0.086037"
      rpy="1.5708 0 3.1416" />
    <parent
      link="hook_link" />
    <child
      link="components_link" />
    <axis
      xyz="0 0 0" />
  </joint>
  <link
    name="x_wheel_link">
    <inertial>
      <origin
        xyz="0 0 0.00075"
        rpy="0 0 0" />
      <mass
        value="0.020913" />
      <inertia
        ixx="1.0298E-05"
        ixy="-2.1176E-22"
        ixz="-3.6746E-24"
        iyy="1.0298E-05"
        iyz="-2.5406E-25"
        izz="2.0587E-05" />
    </inertial>
    <visual>
      <origin
        xyz="0 0 0"
        rpy="0 0 0" />
      <geometry>
        <mesh
          filename="package://cube_pillars/meshes/x_wheel_link.STL" />
      </geometry>
      <material name="">
        <color rgba="0.0 0.0 0.0 0.6" />
      </material>
    </visual>
    <collision>
      <origin
        xyz="0 0 0"
        rpy="0 0 0" />
      <geometry>
        <mesh
          filename="package://cube_pillars/meshes/x_wheel_link.STL" />
      </geometry>
    </collision>
  </link>
  <joint
    name="x_wheel_joint"
    type="continuous">
    <origin
      xyz="-0.03936 -0.0046597 -0.086939"
      rpy="-1.5708 -0.31401 1.5708" />
    <parent
      link="hook_link" />
    <child
      link="x_wheel_link" />
    <axis
      xyz="0 0 -1" />
    <limit
      effort="1"
      velocity="1000" />
  </joint>
  <link
    name="y_wheel_link">
    <inertial>
      <origin
        xyz="2.1684E-19 0 0.00075"
        rpy="0 0 0" />
      <mass
        value="0.020913" />
      <inertia
        ixx="1.0298E-05"
        ixy="2.9646E-21"
        ixz="8.2298E-24"
        iyy="1.0298E-05"
        iyz="-4.0619E-24"
        izz="2.0587E-05" />
    </inertial>
    <visual>
      <origin
        xyz="0 0 0"
        rpy="0 0 0" />
      <geometry>
        <mesh
          filename="package://cube_pillars/meshes/y_wheel_link.STL" />
      </geometry>
      <material name="">
        <color rgba="0.0 0.0 0.0 0.6" />
      </material>
    </visual>
    <collision>
      <origin
        xyz="0 0 0"
        rpy="0 0 0" />
      <geometry>
        <mesh
          filename="package://cube_pillars/meshes/y_wheel_link.STL" />
      </geometry>
    </collision>
  </link>
  <joint
    name="y_wheel_joint"
    type="continuous">
    <origin
      xyz="0.0047528 -0.0046591 -0.042827"
      rpy="2.9871E-16 -1.172E-16 1.0096" />
    <parent
      link="hook_link" />
    <child
      link="y_wheel_link" />
    <axis
      xyz="0 0 1" />
    <limit
      effort="1"
      velocity="1000" />
  </joint>
  <link
    name="z_wheel_link">
    <inertial>
      <origin
        xyz="0 -1.3878E-17 -0.00075"
        rpy="0 0 0" />
      <mass
        value="0.020913" />
      <inertia
        ixx="1.0298E-05"
        ixy="4.2352E-22"
        ixz="8.2746E-24"
        iyy="1.0298E-05"
        iyz="1.2707E-23"
        izz="2.0587E-05" />
    </inertial>
    <visual>
      <origin
        xyz="0 0 0"
        rpy="0 0 0" />
      <geometry>
        <mesh
          filename="package://cube_pillars/meshes/z_wheel_link.STL" />
      </geometry>
      <material name="">
        <color rgba="0.0 0.0 0.0 0.6" />
      </material>
    </visual>
    <collision>
      <origin
        xyz="0 0 0"
        rpy="0 0 0" />
      <geometry>
        <mesh
          filename="package://cube_pillars/meshes/z_wheel_link.STL" />
      </geometry>
    </collision>
  </link>
  <joint
    name="z_wheel_joint"
    type="continuous">
    <origin
      xyz="0.0047528 0.042953 -0.08794"
      rpy="-1.5708 -0.47731 -1.9742E-08" />
    <parent
      link="hook_link" />
    <child
      link="z_wheel_link" />
    <axis
      xyz="0 0 1" />
    <limit
      effort="1"
      velocity="1000" />
  </joint>
  <!-- SDF properties -->
  <!-- Colors -->
  <gazebo reference="base_global_link">
    <material>Gazebo/BlueEmissive</material>
  </gazebo>
  <gazebo reference="hook_link">
    <material>Gazebo/DarkGray</material>
  </gazebo>
  <gazebo reference="components_link">
    <material>Gazebo/PCBGreen</material>
  </gazebo>
  <gazebo reference="x_wheel_link">
    <material>Gazebo/BlackTransparent</material>
  </gazebo>
  <gazebo reference="y_wheel_link">
    <material>Gazebo/BlackTransparent</material>
  </gazebo>
  <gazebo reference="z_wheel_link">
    <material>Gazebo/BlackTransparent</material>
  </gazebo>
  <!-- Dynamics -->
  <gazebo reference="x_wheel_joint">
    <provideFeedback>true</provideFeedback>
  </gazebo>
  <gazebo reference="y_wheel_joint">
    <provideFeedback>true</provideFeedback>
  </gazebo>
  <gazebo reference="z_wheel_joint">
    <provideFeedback>true</provideFeedback>
  </gazebo>
  <!-- Sensors -->
  <gazebo reference="base_global_link">
    <gravity>true</gravity>
    <sensor name="imu_sensor" type="imu">
      <always_on>true</always_on>
      <update_rate>100</update_rate>
      <visualize>true</visualize>
      <topic>__default_topic__</topic>
      <plugin name="imu_plugin" filename="libgazebo_ros_imu_sensor.so">
        <robotNamespace>cube</robotNamespace>
        <topicName>imu_data</topicName>
        <bodyName>base_global_link</bodyName>
        <updateRateHZ>10.0</updateRateHZ>
        <gaussianNoise>0.0</gaussianNoise>
        <xyzOffset>0 0 0</xyzOffset>
        <rpyOffset>0 0 0</rpyOffset>
        <frameName>base_global_link</frameName>
      </plugin>
      <pose>0 0 0 0 0 0</pose>
    </sensor>
  </gazebo>
  <!-- Control -->
  <gazebo>
  <plugin name="gazebo_ros_control" filename="libgazebo_ros_control.so">
    <robotNamespace>/cube</robotNamespace>
  </plugin>
</gazebo>
<transmission name="tran1">
  <type>transmission_interface/SimpleTransmission</type>
  <joint name="x_wheel_joint">
    <hardwareInterface>EffortJointInterface</hardwareInterface>
  </joint>
  <actuator name="motor1">
    <hardwareInterface>EffortJointInterface</hardwareInterface>
    <mechanicalReduction>1</mechanicalReduction>
  </actuator>
</transmission>

<transmission name="tran2">
  <type>transmission_interface/SimpleTransmission</type>
  <joint name="y_wheel_joint">
    <hardwareInterface>EffortJointInterface</hardwareInterface>
  </joint>
  <actuator name="motor2">
    <hardwareInterface>EffortJointInterface</hardwareInterface>
    <mechanicalReduction>1</mechanicalReduction>
  </actuator>
</transmission>

<transmission name="tran3">
  <type>transmission_interface/SimpleTransmission</type>
  <joint name="z_wheel_joint">
    <hardwareInterface>EffortJointInterface</hardwareInterface>
  </joint>
  <actuator name="motor3">
    <hardwareInterface>EffortJointInterface</hardwareInterface>
    <mechanicalReduction>1</mechanicalReduction>
  </actuator>
</transmission>
</robot>